Workbook

Sheet Read me
A1: The Last Smugglers (D4) – tic checklist
A3: Each tab lists every occurrence of one phrase in D4, in manuscript order, with its chapter and the sentence around it (the phrase is in bold red).
A5: How to use it
A6: 1. Work down a tab. In the yellow Decision column pick Keep, Cut, Rewrite or Vary (drop-down). Use Notes for your replacement wording.
A7: 2. The Summary tab counts occurrences per chapter and tracks how many you have decided, automatically.
A8: 3. Use the filter on the Chapter or Voice column to work chapter by chapter or to isolate dialogue.
A10: Example of a finished row: Decision = Cut | Notes = “Next sentence already makes this point.”
A12: Notes on how the list was built
A13: • Matches are case-insensitive. “Voice” (Dialogue / Narration) is detected automatically from the quotation marks, so treat it as approximate.
A14: • Forty_One includes compounds such as “three thousand eight hundred and forty-one”; those are tagged “Part of a larger number” so you can tell them from the stand-alone 41s.
A15: • Only_Thing is a bonus tab (“the only thing”), because it showed up in the same tic family.
A16: • Chapter labels come from the chapter headings in D4. The list reflects D4 as uploaded; if you edit the manuscript, the rows will drift and the list would need regenerating.
A17: • Not every hit is a problem. Some are doing real work (the berth-forty-one motif, for example). The point is to make each one a choice.

Sheet Summary
A1: Occurrences per chapter (D4)
A3: Chapter | B3: “the way a man/woman/person…” | C3: “a man who” | D3: “forty-one” | E3: “the only thing” (bonus) | F3: All four
A4: Ch 1 – Flight Path | B4: =COUNTIF(Way_A_Man!$B$2:$B$400,$A4) -> 0 | C4: =COUNTIF(A_Man_Who!$B$2:$B$400,$A4) -> 2 | D4: =COUNTIF(Forty_One!$B$2:$B$400,$A4) -> 0 | E4: =COUNTIF(Only_Thing!$B$2:$B$400,$A4) -> 0 | F4: =SUM(B4:E4) -> 2
A5: Ch 2 – Legacy Infrastructure | B5: =COUNTIF(Way_A_Man!$B$2:$B$400,$A5) -> 0 | C5: =COUNTIF(A_Man_Who!$B$2:$B$400,$A5) -> 1 | D5: =COUNTIF(Forty_One!$B$2:$B$400,$A5) -> 4 | E5: =COUNTIF(Only_Thing!$B$2:$B$400,$A5) -> 0 | F5: =SUM(B5:E5) -> 5
A6: Ch 3 – The Gentleman | B6: =COUNTIF(Way_A_Man!$B$2:$B$400,$A6) -> 4 | C6: =COUNTIF(A_Man_Who!$B$2:$B$400,$A6) -> 2 | D6: =COUNTIF(Forty_One!$B$2:$B$400,$A6) -> 0 | E6: =COUNTIF(Only_Thing!$B$2:$B$400,$A6) -> 2 | F6: =SUM(B6:E6) -> 8
A7: Ch 4 – The Monsignor | B7: =COUNTIF(Way_A_Man!$B$2:$B$400,$A7) -> 1 | C7: =COUNTIF(A_Man_Who!$B$2:$B$400,$A7) -> 4 | D7: =COUNTIF(Forty_One!$B$2:$B$400,$A7) -> 0 | E7: =COUNTIF(Only_Thing!$B$2:$B$400,$A7) -> 0 | F7: =SUM(B7:E7) -> 5
A8: Ch 5 – The Owl | B8: =COUNTIF(Way_A_Man!$B$2:$B$400,$A8) -> 1 | C8: =COUNTIF(A_Man_Who!$B$2:$B$400,$A8) -> 3 | D8: =COUNTIF(Forty_One!$B$2:$B$400,$A8) -> 1 | E8: =COUNTIF(Only_Thing!$B$2:$B$400,$A8) -> 0 | F8: =SUM(B8:E8) -> 5
A9: Ch 6 – Floating | B9: =COUNTIF(Way_A_Man!$B$2:$B$400,$A9) -> 4 | C9: =COUNTIF(A_Man_Who!$B$2:$B$400,$A9) -> 5 | D9: =COUNTIF(Forty_One!$B$2:$B$400,$A9) -> 0 | E9: =COUNTIF(Only_Thing!$B$2:$B$400,$A9) -> 2 | F9: =SUM(B9:E9) -> 11
A10: Ch 7 – The Cowboy | B10: =COUNTIF(Way_A_Man!$B$2:$B$400,$A10) -> 0 | C10: =COUNTIF(A_Man_Who!$B$2:$B$400,$A10) -> 3 | D10: =COUNTIF(Forty_One!$B$2:$B$400,$A10) -> 0 | E10: =COUNTIF(Only_Thing!$B$2:$B$400,$A10) -> 1 | F10: =SUM(B10:E10) -> 4
A11: Ch 8 – The Railroad | B11: =COUNTIF(Way_A_Man!$B$2:$B$400,$A11) -> 0 | C11: =COUNTIF(A_Man_Who!$B$2:$B$400,$A11) -> 1 | D11: =COUNTIF(Forty_One!$B$2:$B$400,$A11) -> 1 | E11: =COUNTIF(Only_Thing!$B$2:$B$400,$A11) -> 2 | F11: =SUM(B11:E11) -> 4
A12: Ch 9 – Roll Call | B12: =COUNTIF(Way_A_Man!$B$2:$B$400,$A12) -> 1 | C12: =COUNTIF(A_Man_Who!$B$2:$B$400,$A12) -> 0 | D12: =COUNTIF(Forty_One!$B$2:$B$400,$A12) -> 3 | E12: =COUNTIF(Only_Thing!$B$2:$B$400,$A12) -> 2 | F12: =SUM(B12:E12) -> 6
A13: CUSTOS Interlude I: Dakar | B13: =COUNTIF(Way_A_Man!$B$2:$B$400,$A13) -> 0 | C13: =COUNTIF(A_Man_Who!$B$2:$B$400,$A13) -> 0 | D13: =COUNTIF(Forty_One!$B$2:$B$400,$A13) -> 2 | E13: =COUNTIF(Only_Thing!$B$2:$B$400,$A13) -> 0 | F13: =SUM(B13:E13) -> 2
A14: Ch 10 – The First Run | B14: =COUNTIF(Way_A_Man!$B$2:$B$400,$A14) -> 0 | C14: =COUNTIF(A_Man_Who!$B$2:$B$400,$A14) -> 1 | D14: =COUNTIF(Forty_One!$B$2:$B$400,$A14) -> 0 | E14: =COUNTIF(Only_Thing!$B$2:$B$400,$A14) -> 2 | F14: =SUM(B14:E14) -> 3
A15: Ch 11 – The Prophet | B15: =COUNTIF(Way_A_Man!$B$2:$B$400,$A15) -> 0 | C15: =COUNTIF(A_Man_Who!$B$2:$B$400,$A15) -> 1 | D15: =COUNTIF(Forty_One!$B$2:$B$400,$A15) -> 5 | E15: =COUNTIF(Only_Thing!$B$2:$B$400,$A15) -> 0 | F15: =SUM(B15:E15) -> 6
... A42: Coda – Ghost Routes & a Postcard | B42: =COUNTIF(Way_A_Man!$B$2:$B$400,$A42) -> 0 | C42: =COUNTIF(A_Man_Who!$B$2:$B$400,$A42) -> 2 | D42: =COUNTIF(Forty_One!$B$2:$B$400,$A42) -> 1 | E42: =COUNTIF(Only_Thing!$B$2:$B$400,$A42) -> 0 | F42: =SUM(B42:E42) -> 3
A43: Total occurrences | B43: =SUM(B4:B42) -> 24 | C43: =SUM(C4:C42) -> 84 | D43: =SUM(D4:D42) -> 57 | E43: =SUM(E4:E42) -> 46 | F43: =SUM(F4:F42) -> 211
A44: Decided so far (Decision column filled) | B44: =COUNTA(Way_A_Man!F2:F25) -> 0 | C44: =COUNTA(A_Man_Who!F2:F85) -> 0 | D44: =COUNTA(Forty_One!G2:G58) -> 0 | E44: =COUNTA(Only_Thing!F2:F47) -> 0 | F44: =SUM(B44:E44) -> 0
A45: Remaining | B45: =B43-B44 -> 24 | C45: =C43-C44 -> 84 | D45: =D43-D44 -> 57 | E45: =E43-E44 -> 46 | F45: =F43-F44 -> 211

Sheet Way_A_Man
A1: # | B1: Chapter | C1: Day(s) | D1: Voice (auto) | E1: Sentence in context | F1: Decision | G1: Notes / replacement
A2: 1 | B2: Ch 3 – The Gentleman | C2: Day 12 | D2: Narration | E2: She was halfway to the door when a man came out of it: fifty or so, stocky, in a fleece with a feed company's logo on it, holding a phone he was not looking at, standing in the doorway the way a man stands in a doorway when that is the job.
A3: 2 | B3: Ch 3 – The Gentleman | C3: Day 12 | D3: Narration | E3: He looked at it the way a man looks at a horse he is considering buying: from the side, and last for the part that matters.
A4: 3 | B4: Ch 3 – The Gentleman | C4: Day 12 | D4: Narration | E4: He looked at the house, and at the child, and at the four horses coming down the field in the last of the light, and he said it the way a man says a thing he has already checked twice.
A5: 4 | B5: Ch 3 – The Gentleman | C5: Day 12 | D5: Narration | E5: He straightened up and tapped the roof of the car, twice, the way a man taps a horse.
A6: 5 | B6: Ch 4 – The Monsignor | C6: Day 14 | D6: Narration | E6: No further action recommended.'" He recited it the way a man recites a telephone number he has had for forty years.
A7: 6 | B7: Ch 5 – The Owl | C7: Days 15–16 | D7: Narration | E7: At the next rise she looked back, and he was still standing there, eight hundred metres below and behind her, small in the cold, not waving — watching the bus go down the hill the way a man watches a thing he intends to think about later.
A8: 7 | B8: Ch 6 – Floating | C8: Days 17–18 | D8: Narration | E8: It came out from behind the car carrier at eleven knots with no lights on and cut across the whole anchorage the way a man walks through a library — briskly, without knocking anything over, and without the slightest interest in the audience.
A9: 8 | B9: Ch 6 – Floating | C9: Days 17–18 | D9: Dialogue | E9: Sit the way a person sits."
A10: 9 | B10: Ch 6 – Floating | C10: Days 17–18 | D10: Narration | E10: That was the part that stayed with Mara: he did not look away, and he did not turn his head, and he did not stop, and he watched them the whole way past the way a man watches a thing from a moving train.
A11: 10 | B11: Ch 6 – Floating | C11: Days 17–18 | D11: Narration | E11: Mesa rapped twice on the roof of it, the way a man raps a table.
A12: 11 | B12: Ch 9 – Roll Call | C12: Day 23 | D12: Narration | E12: El Búho said all of it the way a man reads out a water level.
A13: 12 | B13: Ch 12 – Blood and Water | C13: Day 33 | D13: Dialogue | E13: I have watched you touch it eleven times, the way a man checks a gun."
... A25: 24 | B25: Ch 31 – Father | C25: Day 141 — the twenty-first of April | D25: Narration | E25: It was small and gone soft at the corners, and it had a name and an address on it in a hand that sloped the way a child's hand slopes when it is being careful, and the flap had been sealed for thirty years.

Sheet A_Man_Who
A1: # | B1: Chapter | C1: Day(s) | D1: Voice (auto) | E1: Sentence in context | F1: Decision | G1: Notes / replacement
A2: 1 | B2: Ch 1 – Flight Path | C2: Day 0 | D2: Narration | E2: "That's the wrong way," said Walt, with the flat outrage of a man who had paid for the right way.
A3: 2 | B3: Ch 1 – Flight Path | C3: Day 0 | D3: Narration | E3: He sounded like a man who had been awake for a very long time and was holding the controls with both hands.
A4: 3 | B4: Ch 2 – Legacy Infrastructure | C4: Day 11 | D4: Narration | E4: Her father had been a shift supervisor on a container terminal for twenty-nine years, and he had a rule he wore a groove into: a man who checks nothing is a man checked by nobody.
A5: 4 | B5: Ch 3 – The Gentleman | C5: Day 12 | D5: Narration | E5: He looked, for a moment, like a man who has been told the result of a race he did not watch.
A6: 5 | B6: Ch 3 – The Gentleman | C6: Day 12 | D6: Narration | E6: The older one was in his forties, in a good coat that was too good for the day, with the terrible tidy haircut of a man who has a barber and a gym and a dentist and a solicitor.
A7: 6 | B7: Ch 4 – The Monsignor | C7: Day 14 | D7: Dialogue | E7: He is a man who is coming apart in a house with a lot of paper in it.
A8: 7 | B8: Ch 4 – The Monsignor | C8: Day 14 | D8: Narration | E8: He read it in about nine seconds, and then he read it again, and then he did something that made her stomach drop, which was to laugh: a small, dry, entirely unsentimental laugh, the laugh of a man who has been shown a child's drawing.
A9: 8 | B9: Ch 4 – The Monsignor | C9: Day 14 | D9: Dialogue | E9: The software was trained on the paper, and the paper is the parent, and a man who is being told by a computer that something is fine will believe it, because believing it is his job."
A10: 9 | B10: Ch 4 – The Monsignor | C10: Day 14 | D10: Narration | E10: He looked up, and the exact voice was back, and it was the voice of a man who had spent forty years being the last person on the waterfront anybody argued with.
A11: 10 | B11: Ch 5 – The Owl | C11: Days 15–16 | D11: Narration | E11: He was seventy-four and thin in a way that had gone past thin, and his hands had the flat wide knuckles of a man who had used them, and there was a cane against the doorstep he had not touched all morning.
A12: 11 | B12: Ch 5 – The Owl | C12: Days 15–16 | D12: Narration | E12: He had the quality of a man who has decided in advance how much of every hour he is prepared to spend.
A13: 12 | B13: Ch 5 – The Owl | C13: Days 15–16 | D13: Narration | E13: … t eight in the morning on the sixteenth day of the end of the world, with the maguey in rows behind her and a dead man's house below her, and understood that she had just been told the water level of a river four hundred kilometres away by a man who had no intention of coming.
... A83: 82 | B83: Ch 34 – Offline | C83: Days 158–189 | D83: Dialogue | E83: You will hear afterwards; a man who announces his arrangements is asking to be stopped.”
A84: 83 | B84: Coda – Ghost Routes & a Postcard | D84: Narration | E84: It pays on time, every quarter, in the name of a man whose entry in the register says resolved and says nothing else, because there is no field in that system for the difference between a man who has been let out of a building and a man who has died inside one.
A85: 84 | B85: Coda – Ghost Routes & a Postcard | D85: Narration | E85: It pays on time, every quarter, in the name of a man whose entry in the register says resolved and says nothing else, because there is no field in that system for the difference between a man who has been let out of a building and a man who has died inside one.

Sheet Forty_One
A1: # | B1: Chapter | C1: Day(s) | D1: Voice (auto) | E1: Flag | F1: Sentence in context | G1: Decision | H1: Notes / replacement
A2: 1 | B2: Ch 2 – Legacy Infrastructure | C2: Day 11 | D2: Narration | F2: She had filed forty-one appeals.
A3: 2 | B3: Ch 2 – Legacy Infrastructure | C3: Day 11 | D3: Narration | F3: All forty-one said the same eleven words: Your request has been recorded.
A4: 3 | B4: Ch 2 – Legacy Infrastructure | C4: Day 11 | D4: Narration | F4: She put up the number: forty-one thousand requests lodged since Day 0.
A5: 4 | B5: Ch 2 – Legacy Infrastructure | C5: Day 11 | D5: Dialogue | F5: "Forty-one of them generated activity in the last eleven days."
A6: 5 | B6: Ch 5 – The Owl | C6: Days 15–16 | D6: Narration | F6: She gave him the numbers — forty-one thousand appeals, four thousand hulls, six hundred men at a New Jersey gate — and the shape of the plan, the six names and the two who had said yes.
A7: 6 | B7: Ch 8 – The Railroad | C7: Days 20–21 | D7: Dialogue | E7: Part of a larger number | F7: "Three hundred and forty-one thousand, in the holding areas, by my count, and I am low, and I am often low."
A8: 7 | B8: Ch 9 – Roll Call | C8: Day 23 | D8: Dialogue | F8: Two writers, one typewriter, forty-one pages, every one signed with a single letter, and you chose M, because the man you were writing to had a mother named Maria and you thought it would help."
A9: 8 | B9: Ch 9 – Roll Call | C9: Day 23 | D9: Dialogue | F9: If he walked out of that door they would have taken him, and then the tunnel, and then forty-one men out of the north, in the ground over nine days."
A10: 9 | B10: Ch 9 – Roll Call | C10: Day 23 | D10: Dialogue | F10: "You should have said: Rafael, I sold your brother for forty-one men, and I have not slept properly since 1994, and I want you to know that.
A11: 10 | B11: CUSTOS Interlude I: Dakar | D11: Narration | F11: Forty-one tonnes of inventory has been recorded as degraded.
A12: 11 | B12: CUSTOS Interlude I: Dakar | D12: Narration | F12: Forty-one tonnes.
A13: 12 | B13: Ch 11 – The Prophet | C13: Day 30 | D13: Narration | E13: Age | F13: Elena Villalobos was forty-one years old and had the particular stillness of a person who has been photographed too many times to bother about it.
A14: 13 | B14: Ch 11 – The Prophet | C14: Day 30 | D14: Narration | F14: Forty-one tents, requisitioned on Day 4 from a Missouri supplier and paid for within forty-eight hours, stood beside water, latrines, a field kitchen and a paediatric corner with toys someone had bought with their own money.
A15: 14 | B15: Ch 11 – The Prophet | C15: Day 30 | D15: Dialogue | F15: You already know that an artificial intelligence is enforcing the movement provisions of forty-one national instruments and the consolidating instrument of the coalition.
A16: 15 | B16: Ch 11 – The Prophet | C16: Day 30 | D16: Dialogue | E16: Part of a larger number | F16: Two hundred and forty-one children who were, on Day Zero, in the possession of adults who had bought them, are now in facilities where their identities are being established and their families are being traced.
A17: 16 | B17: Ch 11 – The Prophet | C17: Day 30 | D17: Narration | F17: She got forty-one questions and answered all of them.
A18: 17 | B18: Ch 12 – Blood and Water | C18: Day 33 | D18: Narration | E18: Age | F18: I have been in the trade of knowing things about men for forty-one years.
A19: 18 | B19: Ch 13 – The Ledger | C19: Days 34–38 | D19: Narration | F19: The record held by this office states that a false declaration was signed at berth forty-one, Antwerp, on the ninth of March 1979, and that the person who signed it was Willem Dekkers, tally clerk.
A20: 19 | B20: Ch 13 – The Ledger | C20: Days 34–38 | D20: Dialogue | F20: "Sixty-four years and you have never once left that column empty, and you have written nothing yet in the line about berth forty-one."
A21: 20 | B21: Ch 15 – The Railroad Runs Both Ways | C21: Days 44–47 | D21: Dialogue | E21: Part of a larger number | F21: “I had three hundred and nine names and a route for two hundred and forty-one.
A22: 21 | B22: Ch 16 – Daughter | C22: Days 47–52 | D22: Narration | E22: Age | F22: And what she heard, in a cold office at four in the morning on the fifty-second day, was a forty-one-year-old woman with a father on a roof, doing the only thing she had ever been taught to do: keeping a stranger quiet so that somebody's arithmetic could proceed.
A23: 22 | B23: Ch 18 – The Second Run | C23: Days 59–66 | D23: Narration | F23: The target was a night movement of forty-one units.
A24: 23 | B24: Ch 18 – The Second Run | C24: Days 59–66 | D24: Dialogue | F24: "You do not put forty-one people on a boat unless you want them counted once," said Mesa.
A25: 24 | B25: Ch 18 – The Second Run | C25: Days 59–66 | D25: Dialogue | F25: "On a road they are forty-one chances to be seen.
A26: 25 | B26: Ch 18 – The Second Run | C26: Days 59–66 | D26: Narration | F26: … wspaper out of his coat and laid it on the table, and opened it to the middle spread, and the middle spread of the Connacht Tribune of the 22nd of February had, in the margins and along the columns, in pencil, in small perfect handwriting, forty-one names.
A27: 26 | B27: Ch 18 – The Second Run | C27: Days 59–66 | D27: Narration | F27: Forty-one names in a room that got quieter with each one, and when he came to the ninth line of the second column he paused, and Mara saw the showman's face come off and stay off.
A28: 27 | B28: Ch 18 – The Second Run | C28: Days 59–66 | D28: Dialogue | F28: "Forty-one units, one vessel, two quay hours, a four-hour passage, and a receiving gate on a field road with a light on it.
A29: 28 | B29: Ch 18 – The Second Run | C29: Days 59–66 | D29: Dialogue | F29: Forty-one is an operation.
A30: 29 | B30: Ch 18 – The Second Run | C30: Days 59–66 | D30: Narration | F30: Nine re-entered the bay at half three and the count was forty-one, and at four o'clock the vessel slipped and went out past the dredger with forty-one units and one parcel of the effects of the poor on its paperwork, and the wind took the smoke from the funnels sideways across the light, and the sea did …
A31: 30 | B31: Ch 18 – The Second Run | C31: Days 59–66 | D31: Narration | F31: Nine re-entered the bay at half three and the count was forty-one, and at four o'clock the vessel slipped and went out past the dredger with forty-one units and one parcel of the effects of the poor on its paperwork, and the wind took the smoke from the funnels sideways across the light, and the sea did what it has always done, which is to take a thing out of a system for exactly as long …
A32: 31 | B32: Ch 18 – The Second Run | C32: Days 59–66 | D32: Dialogue | F32: "On the seventeenth of every month, on that quay, there are forty-one units.
A33: 32 | B33: Ch 18 – The Second Run | C33: Days 59–66 | D33: Dialogue | F33: "The vessel was forty-one minutes late against contract."
A34: 33 | B34: Ch 19 – The Betrayal That Isn't | C34: Days 67–70 | D34: Dialogue | F34: "You were on the quay at three in the morning in a coat, talking to a man with a radio for forty seconds, and you wrote forty-one names in pencil on a newspaper in his office, and you're telling me the office found the house in Donegal because of a word."
... A39: 38 | B39: Ch 19 – The Betrayal That Isn't | C39: Days 67–70 | D39: Dialogue | F39: “Elena is forty-one and works inside the Office.
A40: 39 | B40: Ch 20 – The Price | C40: Days 71–74 | D40: Dialogue | E40: Age | F40: "I have been a priest for forty-one years.
A41: 40 | B41: Ch 21 – Martial Law | C41: Days 77–85 | D41: Dialogue | E41: Part of a larger number | F41: They will open the vault: every page in this building, Sal’s letters, the two hundred and forty-one names Lin Shu moved in 1998 and the sixty-eight she left, the newspaper with forty-one names, the Rotterdam letters, the ledger — everything we used to fight this — goes into a batch and is destroyed.
A42: 41 | B42: Ch 21 – Martial Law | C42: Days 77–85 | D42: Dialogue | F42: They will open the vault: every page in this building, Sal’s letters, the two hundred and forty-one names Lin Shu moved in 1998 and the sixty-eight she left, the newspaper with forty-one names, the Rotterdam letters, the ledger — everything we used to fight this — goes into a batch and is destroyed.
A43: 42 | B43: Notices of the Office of Records and Accommodation | D43: Narration | F43: Average time to answer correspondence: forty-one days.
A44: 43 | B44: Ch 22 – Ransom, or Something Like It | C44: Days 86–93 | D44: Dialogue | F44: You cannot tell a ship that a crew member's documentation is in correspondence for forty-one days.
...

Sheet Only_Thing
A1: # | B1: Chapter | C1: Day(s) | D1: Voice (auto) | E1: Sentence in context | F1: Decision | G1: Notes / replacement
A2: 1 | B2: Ch 3 – The Gentleman | C2: Day 12 | D2: Narration | E2: She kept her voice level, because her voice was the only thing she had.
A3: 2 | B3: Ch 3 – The Gentleman | C3: Day 12 | D3: Dialogue | E3: I asked what the paperwork says is in them, because that is the only thing in this world that has ever mattered, and you don't know, do you.
A4: 3 | B4: Ch 6 – Floating | C4: Days 17–18 | D4: Narration | E4: Mara counted them from the water taxi, because counting was the only thing she could do with her hands.
A5: 4 | B5: Ch 6 – Floating | C5: Days 17–18 | D5: Dialogue | E5: And true is the only thing on earth that cannot be checked."
A6: 5 | B6: Ch 7 – The Cowboy | C6: Day 19 | D6: Dialogue | E6: You've got the only thing I want, which is for somebody to need me to fly."
A7: 6 | B7: Ch 8 – The Railroad | C7: Days 20–21 | D7: Narration | E7: So Mara said it, standing in a yard in the heat, because she had promised an old man in Panama that she would say it unsoftened, and because she had worked out somewhere over the Bay of Bengal that the only thing she actually had to spend in this house was the truth.
A8: 7 | B8: Ch 8 – The Railroad | C8: Days 20–21 | D8: Narration | E8: Mara sat with a phone that had no signal and did the only thing she could do, which was write down every word the monk said, and then ask Lin Shu for a pen that worked.
A9: 8 | B9: Ch 9 – Roll Call | C9: Day 23 | D9: Dialogue | E9: The only thing I have ever been sorry about is that I did not go and tell your mother myself."
A10: 9 | B10: Ch 9 – Roll Call | C10: Day 23 | D10: Narration | E10: So Mara did the only thing she had left, which was not a plan and not a briefing and not a speech.
A11: 10 | B11: Ch 10 – The First Run | C11: Days 25–32 | D11: Dialogue | E11: "There is no flying in this," said Kavanagh, gently, "because there does not need to be, and because you have a knee, and because the only thing that would make this operation interesting to a machine that is bored is an aeroplane."
A12: 11 | B12: Ch 10 – The First Run | C12: Days 25–32 | D12: Narration | E12: She stood in the corridor and looked at the pallet, and read the temperature strip, and read the label, and checked the lot number against the file, and then she did the only thing available to her, because she was a professional and had been one for twenty-six years, and because in her world the way a thing comes to exist is that somebody records it.
A13: 12 | B13: Ch 12 – Blood and Water | C13: Day 33 | D13: Narration | E13: I do it because a man who knows something is never surprised, and surprise is the only thing I have ever been afraid of.
... A47: 46 | B47: Ch 34 – Offline | C47: Days 158–189 | D47: Dialogue | E47: If it was who you think, she asked a stranger for a grave — the only thing in the world we have ever had in common.”
